<?xml version="1.0" encoding="utf-8"?>
<mujoco model="pusher">
	<compiler angle="radian" coordinate="local" inertiafromgeom="true"/>
	<option gravity="0 0 -9.8" integrator="Euler" timestep="0.01"/>

	<worldbody>
		<camera pos="0 0 4.0" name="topview" euler="0 0 0"/>

		<light cutoff="100" diffuse="1 1 1" dir="0 0 -1.3" directional="true" exponent="1" pos="0 0 1.3" specular="0.1 0.1 0.1"/>
		<geom conaffinity="1" condim="3" name="floor" pos="0 0 0" rgba="0.8 0.9 0.8 1" size="10 10 10" type="plane"/>
		<body name="pusher" pos="0.5 0.0 0.11">
			<geom conaffinity="1" condim="1" contype="1" size="0.01 0.2 0.1" pos="0 0 0" mass="10." name="pusher_geom1" rgba="1 0 0 1" type="box"/>
			<joint axis="1 0 0" damping="0.5" name="wrist_slidex" pos="0.0 0.0 0.0" range="-0.5 0.5" type="slide" limited="true"/>
			<joint axis="0 1 0" damping="0.5" name="wrist_slidey" pos="0.0 0.0 0.0" range="-0.5 0.5" type="slide" limited="true"/>
		</body>

		<body name="object0" pos="0.0 0.0 0.03">
			<joint name="object0:joint" type="free" damping="0.001"></joint>
			<geom conaffinity="1" condim="1" contype="1" name="ball" rgba="0 1 0 1" size="0.02" mass="5." type="sphere"/>
		</body>

		<site name="target" pos="-1.0 0 0.03" size="0.04 0.04 0.04" rgba="1 0 0 1" type="sphere"></site>

	</worldbody>
	<actuator>
		<motor ctrllimited="true" ctrlrange="-1.0 1.0" gear="10" joint="wrist_slidex"/>
		<!-- <motor ctrllimited="true" ctrlrange="-1.0 1.0" gear="10000" joint="wrist_slidey"/> -->
	</actuator>
</mujoco>